Workbook

Sheet 1. Bal Sxemi
B2: PREKVALİFİKASİYA — BAL SXEMİ VƏ METODOLOGİYA
B3: Tikinti Tender İştirakçılarının Qiymətləndirmə Meyarları | Ümumi Bal: 100
B5: METODOLOGİYA
B6: • Hər iştirakçı 7 əsas kateqoriya üzrə qiymətləndirilir (ümumi bal: 100). • Məcburi (knock-out) meyarlar 0 bal alarsa, iştirakçı avtomatik RƏDD edilir. • Minimum keçid: 70/100. Ondan aşağı bal alanlar tenderə dəvət edilmir. • Hər alt meyar üzrə xam göstərici cədvəldə avtomatik bal-a çevrilir.
B10: KATEQORİYALAR VƏ BAL PAYLANMASI
B11: Kod | C11: Meyar / Kateqoriya | D11: Max Bal | E11: Çəki % | F11: Qeyd
B12: A | C12: Şirkət Profili və Hüquqi Status | D12: 15 | E12: =D12/100 -> 0.15 | F12: Lisenziya və hüquqi uyğunluq
B13: A.1 | C13: Tikinti fəaliyyəti üzrə lisenziya | D13: 5 | E13: =D13/100 -> 0.05 | F13: MƏCBURİ — 0 bal = RƏDD
B14: A.2 | C14: Fəaliyyət müddəti (illər) | D14: 3 | E14: =D14/100 -> 0.03
B15: A.3 | C15: Şirkətin hüquqi strukturu | D15: 2 | E15: =D15/100 -> 0.02
B16: A.4 | C16: Vergi borcsuzluğu arayışı | D16: 5 | E16: =D16/100 -> 0.05 | F16: MƏCBURİ — 0 bal = RƏDD
B17: B | C17: Maliyyə Vəziyyəti | D17: 20 | E17: =D17/100 -> 0.2 | F17: Son 3 ilin göstəriciləri
B18: B.1 | C18: İllik orta dövriyyə (USD) | D18: 8 | E18: =D18/100 -> 0.08
B19: B.2 | C19: Öz kapitalı (Equity) | D19: 5 | E19: =D19/100 -> 0.05
B20: B.3 | C20: Bank kredit xətti / təminat | D20: 3 | E20: =D20/100 -> 0.03
B21: B.4 | C21: Auditdən keçmiş maliyyə hesabatı | D21: 4 | E21: =D21/100 -> 0.04
B22: C | C22: Texniki Təcrübə və Keçmiş Layihələr | D22: 25 | E22: =D22/100 -> 0.25 | F22: Ən yüksək paylı kateqoriya
B23: C.1 | C23: Son 5 ildə tamamlanmış oxşar layihə sayı | D23: 9 | E23: =D23/100 -> 0.09
B24: C.2 | C24: Ən böyük tamamlanmış layihənin dəyəri | D24: 7 | E24: =D24/100 -> 0.07
B25: C.3 | C25: Hazırda davam edən layihələrin sayı | D25: 4 | E25: =D25/100 -> 0.04
B26: C.4 | C26: ISO 9001 Keyfiyyət Sertifikatı | D26: 5 | E26: =D26/100 -> 0.05
B27: D | C27: Maddi-Texniki Baza | D27: 10 | E27: =D27/100 -> 0.1 | F27: Ofis, avadanlıq, nəqliyyat
B28: D.1 | C28: Ofis və emalatxana sahəsi | D28: 3 | E28: =D28/100 -> 0.03
B29: D.2 | C29: İş avadanlığı və alətlər siyahısı | D29: 4 | E29: =D29/100 -> 0.04
B30: D.3 | C30: Nəqliyyat və yük maşın parkı | D30: 3 | E30: =D30/100 -> 0.03
B31: E | C31: Kadr Resursları | D31: 15 | E31: =D31/100 -> 0.15 | F31: Heyət və ixtisas
B32: E.1 | C32: Ümumi daimi heyət sayı | D32: 4 | E32: =D32/100 -> 0.04
B33: E.2 | C33: Mühəndis / Texniki heyət sayı | D33: 4 | E33: =D33/100 -> 0.04
B34: E.3 | C34: İSG (HSE) mütəxəssisi | D34: 3 | E34: =D34/100 -> 0.03
B35: E.4 | C35: Daimi subpodratçı bazası | D35: 4 | E35: =D35/100 -> 0.04
B36: F | C36: İSG (HSE) və Keyfiyyət Sistemi | D36: 10 | E36: =D36/100 -> 0.1 | F36: Təhlükəsizlik prioriteti
B37: F.1 | C37: İSG sertifikatı və planı | D37: 4 | E37: =D37/100 -> 0.04 | F37: MƏCBURİ — 0 bal = RƏDD
B38: F.2 | C38: ISO 14001 / 45001 sertifikatları | D38: 3 | E38: =D38/100 -> 0.03
B39: F.3 | C39: Son 3 ildə bədbəxt hadisə statistikası | D39: 3 | E39: =D39/100 -> 0.03
B40: G | C40: Sığorta, Zəmanət və Referanslar | D40: 5 | E40: =D40/100 -> 0.05 | F40: Risklərin idarə olunması
B41: G.1 | C41: Peşəkar və ümumi məsuliyyət sığortası | D41: 3 | E41: =D41/100 -> 0.03
B42: G.2 | C42: Keçmiş müştərilərdən referans sayı | D42: 2 | E42: =D42/100 -> 0.02
B44: ÜMUMİ BAL | D44: =D12+D17+D22+D27+D31+D36+D40 -> 100 | E44: =D44/100 -> 1 | F44: Min. keçid: 70/100
B45: NƏTİCƏ TƏSNİFATI
B46: Bal Aralığı | C46: Sinif | D46: Qərar
...

Sheet 2. İştirakçı Məlumatları
B2: İŞTİRAKÇI MƏLUMATLARI — Ümumi Profil
B3: ⚠ Sarı xanaları doldurun. Məlumatlar digər vərəqələrdə avtomatik görünəcəkdir.
B5: Məlumat Sahəsi | C5: İştirakçı №1 | D5: İştirakçı №2 | E5: İştirakçı №3 | F5: İştirakçı №4 | G5: İştirakçı №5 | H5: İştirakçı №6 | I5: İştirakçı №7 | J5: İştirakçı №8 | K5: İştirakçı №9 | L5: İştirakçı №10 | M5: İştirakçı №11 | N5: İştirakçı №12 | O5: İştirakçı №13 | P5: İştirakçı №14 | Q5: İştirakçı №15
B6: Şirkətin tam adı
B7: Ticarət reyestr nömrəsi
B8: Qeydiyyat ili
B9: Ünvan
B10: Əsas əlaqə şəxsi
B11: Vəzifə
B12: Telefon / WhatsApp
B13: E-poçt
B14: Veb sayt
B15: Ümumi heyət sayı
B16: Mühəndis heyəti sayı

Sheet 3. Cavablar (Xam Göstəricilər)
B2: CAVAB CƏDVƏLİ — Xam Göstəricilər və Sənəd Yoxlanışı
B3: ⚠ Sarı xanalara subpodratçıdan alınmış cavabları / sənəd üzrə rəqəm və ya 0–3 qiymət daxil edin.
B5: Kod | C5: Göstərici / Sual | D5: Ölçü Vahidi | E5: ='2. İştirakçı Məlumatları'!C6 -> 0 | F5: ='2. İştirakçı Məlumatları'!D6 -> 0 | G5: ='2. İştirakçı Məlumatları'!E6 -> 0 | H5: ='2. İştirakçı Məlumatları'!F6 -> 0 | I5: ='2. İştirakçı Məlumatları'!G6 -> 0 | J5: ='2. İştirakçı Məlumatları'!H6 -> 0 | K5: ='2. İştirakçı Məlumatları'!I6 -> 0 | L5: ='2. İştirakçı Məlumatları'!J6 -> 0 | ... S5: ='2. İştirakçı Məlumatları'!Q6 -> 0
B6: A. ŞİRKƏT PROFİLİ
B7: A.1 | C7: Tikinti lisenziyası statusu | D7: 0–3 qiymət
B8: A.2 | C8: Fəaliyyət ili (qeydiyyatdan bəri) | D8: il
B9: A.3 | C9: Hüquqi strukturun şəffaflığı | D9: 0–3 qiymət
B10: A.4 | C10: Vergi borcsuzluğu arayışı (son 3 ay) | D10: 0–3 qiymət
B11: B. MALİYYƏ VƏZİYYƏTİ
B12: B.1 | C12: Son 3 ilin orta illik dövriyyəsi | D12: AZN
B13: B.2 | C13: Öz kapitalı (son bilans) | D13: AZN
B14: B.3 | C14: Bank kredit xətti / təminat | D14: 0–3 qiymət
B15: B.4 | C15: Auditdən keçmiş maliyyə hesabatı | D15: 0–3 qiymət
B16: C. TEXNİKİ TƏCRÜBƏ
B17: C.1 | C17: Son 5 ildə oxşar layihə sayı | D17: ədəd
B18: C.2 | C18: Ən böyük tamamlanmış layihənin dəyəri | D18: AZN
B19: C.3 | C19: Hazırda davam edən layihə sayı | D19: ədəd
B20: C.4 | C20: ISO 9001 sertifikatı | D20: 0–3 qiymət
B21: D. MADDİ-TEXNİKİ BAZA
B22: D.1 | C22: Ofis və emalatxana sahəsinin mövcudluğu | D22: 0–3 qiymət
B23: D.2 | C23: İş avadanlığı və alətlərin yetərliliyi | D23: 0–3 qiymət
B24: D.3 | C24: Nəqliyyat və yük maşın parkı | D24: 0–3 qiymət
B25: E. KADR RESURSLARI
B26: E.1 | C26: Ümumi daimi heyət sayı | D26: nəfər
B27: E.2 | C27: Mühəndis / texniki heyət sayı | D27: nəfər
B28: E.3 | C28: Tam ştatlı İSG (HSE) mütəxəssisi | D28: 0–3 qiymət
B29: E.4 | C29: Daimi subpodratçı bazası | D29: 0–3 qiymət
B30: F. HSE VƏ KEYFİYYƏT
B31: F.1 | C31: HSE sertifikatı və planı (MƏCBURİ) | D31: 0–3 qiymət
B32: F.2 | C32: ISO 14001 / 45001 sertifikatları | D32: 0–3 qiymət
B33: F.3 | C33: Son 3 ildə bədbəxt hadisə göstəricisi | D33: 0–3 qiymət
B34: G. SIĞORTA VƏ REFERANSLAR
B35: G.1 | C35: Peşəkar və ümumi məsuliyyət sığortası | D35: 0–3 qiymət
B36: G.2 | C36: Keçmiş müştərilərdən referans sayı | D36: ədəd

Sheet 4. Bal Hesablaması
B2: BAL HESABLAMASI — Avtomatik Formulalar
B3: Hər meyar üzrə ballar 'Cavablar' vərəqəsindəki xam göstəricilərə əsasən avtomatik hesablanır.
B5: Kod | C5: Meyar | D5: Max Bal | E5: ='2. İştirakçı Məlumatları'!C6 -> 0 | F5: ='2. İştirakçı Məlumatları'!D6 -> 0 | G5: ='2. İştirakçı Məlumatları'!E6 -> 0 | H5: ='2. İştirakçı Məlumatları'!F6 -> 0 | I5: ='2. İştirakçı Məlumatları'!G6 -> 0 | J5: ='2. İştirakçı Məlumatları'!H6 -> 0 | K5: ='2. İştirakçı Məlumatları'!I6 -> 0 | L5: ='2. İştirakçı Məlumatları'!J6 -> 0 | ... S5: ='2. İştirakçı Məlumatları'!Q6 -> 0
B6: A. ŞİRKƏT PROFİLİ (15 bal)
B7: A.1 | C7: Tikinti lisenziyası statusu | D7: 5 | E7: =ROUND('3. Cavablar (Xam Göstəricilər)'!E7/3*5,1) -> 0 | F7: =ROUND('3. Cavablar (Xam Göstəricilər)'!F7/3*5,1) -> 0 | G7: =ROUND('3. Cavablar (Xam Göstəricilər)'!G7/3*5,1) -> 0 | H7: =ROUND('3. Cavablar (Xam Göstəricilər)'!H7/3*5,1) -> 0 | I7: =ROUND('3. Cavablar (Xam Göstəricilər)'!I7/3*5,1) -> 0 | J7: =ROUND('3. Cavablar (Xam Göstəricilər)'!J7/3*5,1) -> 0 | K7: =ROUND('3. Cavablar (Xam Göstəricilər)'!K7/3*5,1) -> 0 | L7: =ROUND('3. Cavablar (Xam Göstəricilər)'!L7/3*5,1) -> 0 | ... S7: =ROUND('3. Cavablar (Xam Göstəricilər)'!S7/3*5,1) -> 0
B8: A.2 | C8: Fəaliyyət ili (qeydiyyatdan bəri) | D8: 3 | E8: =IF('3. Cavablar (Xam Göstəricilər)'!E8=0,0,IF('3. Cavablar (Xam Göstəricilər)'!E8<=3,1,IF('3. Cavablar (Xam Göstəricilər)'!E8<=7,2,3))) -> 0 | F8: =IF('3. Cavablar (Xam Göstəricilər)'!F8=0,0,IF('3. Cavablar (Xam Göstəricilər)'!F8<=3,1,IF('3. Cavablar (Xam Göstəricilər)'!F8<=7,2,3))) -> 0 | G8: =IF('3. Cavablar (Xam Göstəricilər)'!G8=0,0,IF('3. Cavablar (Xam Göstəricilər)'!G8<=3,1,IF('3. Cavablar (Xam Göstəricilər)'!G8<=7,2,3))) -> 0 | H8: =IF('3. Cavablar (Xam Göstəricilər)'!H8=0,0,IF('3. Cavablar (Xam Göstəricilər)'!H8<=3,1,IF('3. Cavablar (Xam Göstəricilər)'!H8<=7,2,3))) -> 0 | I8: =IF('3. Cavablar (Xam Göstəricilər)'!I8=0,0,IF('3. Cavablar (Xam Göstəricilər)'!I8<=3,1,IF('3. Cavablar (Xam Göstəricilər)'!I8<=7,2,3))) -> 0 | J8: =IF('3. Cavablar (Xam Göstəricilər)'!J8=0,0,IF('3. Cavablar (Xam Göstəricilər)'!J8<=3,1,IF('3. Cavablar (Xam Göstəricilər)'!J8<=7,2,3))) -> 0 | K8: =IF('3. Cavablar (Xam Göstəricilər)'!K8=0,0,IF('3. Cavablar (Xam Göstəricilər)'!K8<=3,1,IF('3. Cavablar (Xam Göstəricilər)'!K8<=7,2,3))) -> 0 | L8: =IF('3. Cavablar (Xam Göstəricilər)'!L8=0,0,IF('3. Cavablar (Xam Göstəricilər)'!L8<=3,1,IF('3. Cavablar (Xam Göstəricilər)'!L8<=7,2,3))) -> 0 | ... S8: =IF('3. Cavablar (Xam Göstəricilər)'!S8=0,0,IF('3. Cavablar (Xam Göstəricilər)'!S8<=3,1,IF('3. Cavablar (Xam Göstəricilər)'!S8<=7,2,3))) -> 0
B9: A.3 | C9: Hüquqi strukturun şəffaflığı | D9: 2 | E9: =ROUND('3. Cavablar (Xam Göstəricilər)'!E9/3*2,1) -> 0 | F9: =ROUND('3. Cavablar (Xam Göstəricilər)'!F9/3*2,1) -> 0 | G9: =ROUND('3. Cavablar (Xam Göstəricilər)'!G9/3*2,1) -> 0 | H9: =ROUND('3. Cavablar (Xam Göstəricilər)'!H9/3*2,1) -> 0 | I9: =ROUND('3. Cavablar (Xam Göstəricilər)'!I9/3*2,1) -> 0 | J9: =ROUND('3. Cavablar (Xam Göstəricilər)'!J9/3*2,1) -> 0 | K9: =ROUND('3. Cavablar (Xam Göstəricilər)'!K9/3*2,1) -> 0 | L9: =ROUND('3. Cavablar (Xam Göstəricilər)'!L9/3*2,1) -> 0 | ... S9: =ROUND('3. Cavablar (Xam Göstəricilər)'!S9/3*2,1) -> 0
B10: A.4 | C10: Vergi borcsuzluğu arayışı (son 3 ay) | D10: 5 | E10: =ROUND('3. Cavablar (Xam Göstəricilər)'!E10/3*5,1) -> 0 | F10: =ROUND('3. Cavablar (Xam Göstəricilər)'!F10/3*5,1) -> 0 | G10: =ROUND('3. Cavablar (Xam Göstəricilər)'!G10/3*5,1) -> 0 | H10: =ROUND('3. Cavablar (Xam Göstəricilər)'!H10/3*5,1) -> 0 | I10: =ROUND('3. Cavablar (Xam Göstəricilər)'!I10/3*5,1) -> 0 | J10: =ROUND('3. Cavablar (Xam Göstəricilər)'!J10/3*5,1) -> 0 | K10: =ROUND('3. Cavablar (Xam Göstəricilər)'!K10/3*5,1) -> 0 | L10: =ROUND('3. Cavablar (Xam Göstəricilər)'!L10/3*5,1) -> 0 | ... S10: =ROUND('3. Cavablar (Xam Göstəricilər)'!S10/3*5,1) -> 0
B11: B. MALİYYƏ VƏZİYYƏTİ (20 bal)
B12: B.1 | C12: Son 3 ilin orta illik dövriyyəsi | D12: 8 | E12: =IF('3. Cavablar (Xam Göstəricilər)'!E12<500000,0,IF('3. Cavablar (Xam Göstəricilər)'!E12<1000000,ROUND(8*0.25,1),IF('3. Cavablar (Xam Göstəricilər)'!E12<5000000,ROUND(8*0.5,1),IF('3. Cavablar (Xam Göstəricilər)'!E12<10000000,ROUND(8*0.75,1),8)))) -> 0 | F12: =IF('3. Cavablar (Xam Göstəricilər)'!F12<500000,0,IF('3. Cavablar (Xam Göstəricilər)'!F12<1000000,ROUND(8*0.25,1),IF('3. Cavablar (Xam Göstəricilər)'!F12<5000000,ROUND(8*0.5,1),IF('3. Cavablar (Xam Göstəricilər)'!F12<10000000,ROUND(8*0.75,1),8)))) -> 0 | G12: =IF('3. Cavablar (Xam Göstəricilər)'!G12<500000,0,IF('3. Cavablar (Xam Göstəricilər)'!G12<1000000,ROUND(8*0.25,1),IF('3. Cavablar (Xam Göstəricilər)'!G12<5000000,ROUND(8*0.5,1),IF('3. Cavablar (Xam Göstəricilər)'!G12<10000000,ROUND(8*0.75,1),8)))) -> 0 | H12: =IF('3. Cavablar (Xam Göstəricilər)'!H12<500000,0,IF('3. Cavablar (Xam Göstəricilər)'!H12<1000000,ROUND(8*0.25,1),IF('3. Cavablar (Xam Göstəricilər)'!H12<5000000,ROUND(8*0.5,1),IF('3. Cavablar (Xam Göstəricilər)'!H12<10000000,ROUND(8*0.75,1),8)))) -> 0 | I12: =IF('3. Cavablar (Xam Göstəricilər)'!I12<500000,0,IF('3. Cavablar (Xam Göstəricilər)'!I12<1000000,ROUND(8*0.25,1),IF('3. Cavablar (Xam Göstəricilər)'!I12<5000000,ROUND(8*0.5,1),IF('3. Cavablar (Xam Göstəricilər)'!I12<10000000,ROUND(8*0.75,1),8)))) -> 0 | J12: =IF('3. Cavablar (Xam Göstəricilər)'!J12<500000,0,IF('3. Cavablar (Xam Göstəricilər)'!J12<1000000,ROUND(8*0.25,1),IF('3. Cavablar (Xam Göstəricilər)'!J12<5000000,ROUND(8*0.5,1),IF('3. Cavablar (Xam Göstəricilər)'!J12<10000000,ROUND(8*0.75,1),8)))) -> 0 | K12: =IF('3. Cavablar (Xam Göstəricilər)'!K12<500000,0,IF('3. Cavablar (Xam Göstəricilər)'!K12<1000000,ROUND(8*0.25,1),IF('3. Cavablar (Xam Göstəricilər)'!K12<5000000,ROUND(8*0.5,1),IF('3. Cavablar (Xam Göstəricilər)'!K12<10000000,ROUND(8*0.75,1),8)))) -> 0 | L12: =IF('3. Cavablar (Xam Göstəricilər)'!L12<500000,0,IF('3. Cavablar (Xam Göstəricilər)'!L12<1000000,ROUND(8*0.25,1),IF('3. Cavablar (Xam Göstəricilər)'!L12<5000000,ROUND(8*0.5,1),IF('3. Cavablar (Xam Göstəricilər)'!L12<10000000,ROUND(8*0.75,1),8)))) -> 0 | ... S12: =IF('3. Cavablar (Xam Göstəricilər)'!S12<500000,0,IF('3. Cavablar (Xam Göstəricilər)'!S12<1000000,ROUND(8*0.25,1),IF('3. Cavablar (Xam Göstəricilər)'!S12<5000000,ROUND(8*0.5,1),IF('3. Cavablar (Xam Göstəricilər)'!S12<10000000,ROUND(8*0.75,1),8)))) -> 0
B13: B.2 | C13: Öz kapitalı (son bilans) | D13: 5 | E13: =IF('3. Cavablar (Xam Göstəricilər)'!E13<500000,0,IF('3. Cavablar (Xam Göstəricilər)'!E13<1000000,ROUND(5*0.3,1),IF('3. Cavablar (Xam Göstəricilər)'!E13<2500000,ROUND(5*0.6,1),5))) -> 0 | F13: =IF('3. Cavablar (Xam Göstəricilər)'!F13<500000,0,IF('3. Cavablar (Xam Göstəricilər)'!F13<1000000,ROUND(5*0.3,1),IF('3. Cavablar (Xam Göstəricilər)'!F13<2500000,ROUND(5*0.6,1),5))) -> 0 | G13: =IF('3. Cavablar (Xam Göstəricilər)'!G13<500000,0,IF('3. Cavablar (Xam Göstəricilər)'!G13<1000000,ROUND(5*0.3,1),IF('3. Cavablar (Xam Göstəricilər)'!G13<2500000,ROUND(5*0.6,1),5))) -> 0 | H13: =IF('3. Cavablar (Xam Göstəricilər)'!H13<500000,0,IF('3. Cavablar (Xam Göstəricilər)'!H13<1000000,ROUND(5*0.3,1),IF('3. Cavablar (Xam Göstəricilər)'!H13<2500000,ROUND(5*0.6,1),5))) -> 0 | I13: =IF('3. Cavablar (Xam Göstəricilər)'!I13<500000,0,IF('3. Cavablar (Xam Göstəricilər)'!I13<1000000,ROUND(5*0.3,1),IF('3. Cavablar (Xam Göstəricilər)'!I13<2500000,ROUND(5*0.6,1),5))) -> 0 | J13: =IF('3. Cavablar (Xam Göstəricilər)'!J13<500000,0,IF('3. Cavablar (Xam Göstəricilər)'!J13<1000000,ROUND(5*0.3,1),IF('3. Cavablar (Xam Göstəricilər)'!J13<2500000,ROUND(5*0.6,1),5))) -> 0 | K13: =IF('3. Cavablar (Xam Göstəricilər)'!K13<500000,0,IF('3. Cavablar (Xam Göstəricilər)'!K13<1000000,ROUND(5*0.3,1),IF('3. Cavablar (Xam Göstəricilər)'!K13<2500000,ROUND(5*0.6,1),5))) -> 0 | L13: =IF('3. Cavablar (Xam Göstəricilər)'!L13<500000,0,IF('3. Cavablar (Xam Göstəricilər)'!L13<1000000,ROUND(5*0.3,1),IF('3. Cavablar (Xam Göstəricilər)'!L13<2500000,ROUND(5*0.6,1),5))) -> 0 | ... S13: =IF('3. Cavablar (Xam Göstəricilər)'!S13<500000,0,IF('3. Cavablar (Xam Göstəricilər)'!S13<1000000,ROUND(5*0.3,1),IF('3. Cavablar (Xam Göstəricilər)'!S13<2500000,ROUND(5*0.6,1),5))) -> 0
B14: B.3 | C14: Bank kredit xətti / təminat | D14: 3 | E14: =ROUND('3. Cavablar (Xam Göstəricilər)'!E14/3*3,1) -> 0 | F14: =ROUND('3. Cavablar (Xam Göstəricilər)'!F14/3*3,1) -> 0 | G14: =ROUND('3. Cavablar (Xam Göstəricilər)'!G14/3*3,1) -> 0 | H14: =ROUND('3. Cavablar (Xam Göstəricilər)'!H14/3*3,1) -> 0 | I14: =ROUND('3. Cavablar (Xam Göstəricilər)'!I14/3*3,1) -> 0 | J14: =ROUND('3. Cavablar (Xam Göstəricilər)'!J14/3*3,1) -> 0 | K14: =ROUND('3. Cavablar (Xam Göstəricilər)'!K14/3*3,1) -> 0 | L14: =ROUND('3. Cavablar (Xam Göstəricilər)'!L14/3*3,1) -> 0 | ... S14: =ROUND('3. Cavablar (Xam Göstəricilər)'!S14/3*3,1) -> 0
B15: B.4 | C15: Auditdən keçmiş maliyyə hesabatı | D15: 4 | E15: =ROUND('3. Cavablar (Xam Göstəricilər)'!E15/3*4,1) -> 0 | F15: =ROUND('3. Cavablar (Xam Göstəricilər)'!F15/3*4,1) -> 0 | G15: =ROUND('3. Cavablar (Xam Göstəricilər)'!G15/3*4,1) -> 0 | H15: =ROUND('3. Cavablar (Xam Göstəricilər)'!H15/3*4,1) -> 0 | I15: =ROUND('3. Cavablar (Xam Göstəricilər)'!I15/3*4,1) -> 0 | J15: =ROUND('3. Cavablar (Xam Göstəricilər)'!J15/3*4,1) -> 0 | K15: =ROUND('3. Cavablar (Xam Göstəricilər)'!K15/3*4,1) -> 0 | L15: =ROUND('3. Cavablar (Xam Göstəricilər)'!L15/3*4,1) -> 0 | ... S15: =ROUND('3. Cavablar (Xam Göstəricilər)'!S15/3*4,1) -> 0
B16: C. TEXNİKİ TƏCRÜBƏ (25 bal)
B17: C.1 | C17: Son 5 ildə oxşar layihə sayı | D17: 9 | E17: =IF('3. Cavablar (Xam Göstəricilər)'!E17<2,0,IF('3. Cavablar (Xam Göstəricilər)'!E17<=4,ROUND(9*0.3,1),IF('3. Cavablar (Xam Göstəricilər)'!E17<=9,ROUND(9*0.7,1),9))) -> 0 | F17: =IF('3. Cavablar (Xam Göstəricilər)'!F17<2,0,IF('3. Cavablar (Xam Göstəricilər)'!F17<=4,ROUND(9*0.3,1),IF('3. Cavablar (Xam Göstəricilər)'!F17<=9,ROUND(9*0.7,1),9))) -> 0 | G17: =IF('3. Cavablar (Xam Göstəricilər)'!G17<2,0,IF('3. Cavablar (Xam Göstəricilər)'!G17<=4,ROUND(9*0.3,1),IF('3. Cavablar (Xam Göstəricilər)'!G17<=9,ROUND(9*0.7,1),9))) -> 0 | H17: =IF('3. Cavablar (Xam Göstəricilər)'!H17<2,0,IF('3. Cavablar (Xam Göstəricilər)'!H17<=4,ROUND(9*0.3,1),IF('3. Cavablar (Xam Göstəricilər)'!H17<=9,ROUND(9*0.7,1),9))) -> 0 | I17: =IF('3. Cavablar (Xam Göstəricilər)'!I17<2,0,IF('3. Cavablar (Xam Göstəricilər)'!I17<=4,ROUND(9*0.3,1),IF('3. Cavablar (Xam Göstəricilər)'!I17<=9,ROUND(9*0.7,1),9))) -> 0 | J17: =IF('3. Cavablar (Xam Göstəricilər)'!J17<2,0,IF('3. Cavablar (Xam Göstəricilər)'!J17<=4,ROUND(9*0.3,1),IF('3. Cavablar (Xam Göstəricilər)'!J17<=9,ROUND(9*0.7,1),9))) -> 0 | K17: =IF('3. Cavablar (Xam Göstəricilər)'!K17<2,0,IF('3. Cavablar (Xam Göstəricilər)'!K17<=4,ROUND(9*0.3,1),IF('3. Cavablar (Xam Göstəricilər)'!K17<=9,ROUND(9*0.7,1),9))) -> 0 | L17: =IF('3. Cavablar (Xam Göstəricilər)'!L17<2,0,IF('3. Cavablar (Xam Göstəricilər)'!L17<=4,ROUND(9*0.3,1),IF('3. Cavablar (Xam Göstəricilər)'!L17<=9,ROUND(9*0.7,1),9))) -> 0 | ... S17: =IF('3. Cavablar (Xam Göstəricilər)'!S17<2,0,IF('3. Cavablar (Xam Göstəricilər)'!S17<=4,ROUND(9*0.3,1),IF('3. Cavablar (Xam Göstəricilər)'!S17<=9,ROUND(9*0.7,1),9))) -> 0
B18: C.2 | C18: Ən böyük tamamlanmış layihənin dəyəri | D18: 7 | E18: =IF('3. Cavablar (Xam Göstəricilər)'!E18<1000000,0,IF('3. Cavablar (Xam Göstəricilər)'!E18<3000000,ROUND(7*0.4,1),IF('3. Cavablar (Xam Göstəricilər)'!E18<7000000,ROUND(7*0.75,1),7))) -> 0 | F18: =IF('3. Cavablar (Xam Göstəricilər)'!F18<1000000,0,IF('3. Cavablar (Xam Göstəricilər)'!F18<3000000,ROUND(7*0.4,1),IF('3. Cavablar (Xam Göstəricilər)'!F18<7000000,ROUND(7*0.75,1),7))) -> 0 | G18: =IF('3. Cavablar (Xam Göstəricilər)'!G18<1000000,0,IF('3. Cavablar (Xam Göstəricilər)'!G18<3000000,ROUND(7*0.4,1),IF('3. Cavablar (Xam Göstəricilər)'!G18<7000000,ROUND(7*0.75,1),7))) -> 0 | H18: =IF('3. Cavablar (Xam Göstəricilər)'!H18<1000000,0,IF('3. Cavablar (Xam Göstəricilər)'!H18<3000000,ROUND(7*0.4,1),IF('3. Cavablar (Xam Göstəricilər)'!H18<7000000,ROUND(7*0.75,1),7))) -> 0 | I18: =IF('3. Cavablar (Xam Göstəricilər)'!I18<1000000,0,IF('3. Cavablar (Xam Göstəricilər)'!I18<3000000,ROUND(7*0.4,1),IF('3. Cavablar (Xam Göstəricilər)'!I18<7000000,ROUND(7*0.75,1),7))) -> 0 | J18: =IF('3. Cavablar (Xam Göstəricilər)'!J18<1000000,0,IF('3. Cavablar (Xam Göstəricilər)'!J18<3000000,ROUND(7*0.4,1),IF('3. Cavablar (Xam Göstəricilər)'!J18<7000000,ROUND(7*0.75,1),7))) -> 0 | K18: =IF('3. Cavablar (Xam Göstəricilər)'!K18<1000000,0,IF('3. Cavablar (Xam Göstəricilər)'!K18<3000000,ROUND(7*0.4,1),IF('3. Cavablar (Xam Göstəricilər)'!K18<7000000,ROUND(7*0.75,1),7))) -> 0 | L18: =IF('3. Cavablar (Xam Göstəricilər)'!L18<1000000,0,IF('3. Cavablar (Xam Göstəricilər)'!L18<3000000,ROUND(7*0.4,1),IF('3. Cavablar (Xam Göstəricilər)'!L18<7000000,ROUND(7*0.75,1),7))) -> 0 | ... S18: =IF('3. Cavablar (Xam Göstəricilər)'!S18<1000000,0,IF('3. Cavablar (Xam Göstəricilər)'!S18<3000000,ROUND(7*0.4,1),IF('3. Cavablar (Xam Göstəricilər)'!S18<7000000,ROUND(7*0.75,1),7))) -> 0
B19: C.3 | C19: Hazırda davam edən layihə sayı | D19: 4 | E19: =IF('3. Cavablar (Xam Göstəricilər)'!E19=0,ROUND(4*0.25,1),IF('3. Cavablar (Xam Göstəricilər)'!E19<=3,ROUND(4*0.5,1),IF('3. Cavablar (Xam Göstəricilər)'!E19<=6,4,ROUND(4*0.75,1)))) -> 1 | F19: =IF('3. Cavablar (Xam Göstəricilər)'!F19=0,ROUND(4*0.25,1),IF('3. Cavablar (Xam Göstəricilər)'!F19<=3,ROUND(4*0.5,1),IF('3. Cavablar (Xam Göstəricilər)'!F19<=6,4,ROUND(4*0.75,1)))) -> 1 | G19: =IF('3. Cavablar (Xam Göstəricilər)'!G19=0,ROUND(4*0.25,1),IF('3. Cavablar (Xam Göstəricilər)'!G19<=3,ROUND(4*0.5,1),IF('3. Cavablar (Xam Göstəricilər)'!G19<=6,4,ROUND(4*0.75,1)))) -> 1 | H19: =IF('3. Cavablar (Xam Göstəricilər)'!H19=0,ROUND(4*0.25,1),IF('3. Cavablar (Xam Göstəricilər)'!H19<=3,ROUND(4*0.5,1),IF('3. Cavablar (Xam Göstəricilər)'!H19<=6,4,ROUND(4*0.75,1)))) -> 1 | I19: =IF('3. Cavablar (Xam Göstəricilər)'!I19=0,ROUND(4*0.25,1),IF('3. Cavablar (Xam Göstəricilər)'!I19<=3,ROUND(4*0.5,1),IF('3. Cavablar (Xam Göstəricilər)'!I19<=6,4,ROUND(4*0.75,1)))) -> 1 | J19: =IF('3. Cavablar (Xam Göstəricilər)'!J19=0,ROUND(4*0.25,1),IF('3. Cavablar (Xam Göstəricilər)'!J19<=3,ROUND(4*0.5,1),IF('3. Cavablar (Xam Göstəricilər)'!J19<=6,4,ROUND(4*0.75,1)))) -> 1 | K19: =IF('3. Cavablar (Xam Göstəricilər)'!K19=0,ROUND(4*0.25,1),IF('3. Cavablar (Xam Göstəricilər)'!K19<=3,ROUND(4*0.5,1),IF('3. Cavablar (Xam Göstəricilər)'!K19<=6,4,ROUND(4*0.75,1)))) -> 1 | L19: =IF('3. Cavablar (Xam Göstəricilər)'!L19=0,ROUND(4*0.25,1),IF('3. Cavablar (Xam Göstəricilər)'!L19<=3,ROUND(4*0.5,1),IF('3. Cavablar (Xam Göstəricilər)'!L19<=6,4,ROUND(4*0.75,1)))) -> 1 | ... S19: =IF('3. Cavablar (Xam Göstəricilər)'!S19=0,ROUND(4*0.25,1),IF('3. Cavablar (Xam Göstəricilər)'!S19<=3,ROUND(4*0.5,1),IF('3. Cavablar (Xam Göstəricilər)'!S19<=6,4,ROUND(4*0.75,1)))) -> 1
B20: C.4 | C20: ISO 9001 sertifikatı | D20: 5 | E20: =ROUND('3. Cavablar (Xam Göstəricilər)'!E20/3*5,1) -> 0 | F20: =ROUND('3. Cavablar (Xam Göstəricilər)'!F20/3*5,1) -> 0 | G20: =ROUND('3. Cavablar (Xam Göstəricilər)'!G20/3*5,1) -> 0 | H20: =ROUND('3. Cavablar (Xam Göstəricilər)'!H20/3*5,1) -> 0 | I20: =ROUND('3. Cavablar (Xam Göstəricilər)'!I20/3*5,1) -> 0 | J20: =ROUND('3. Cavablar (Xam Göstəricilər)'!J20/3*5,1) -> 0 | K20: =ROUND('3. Cavablar (Xam Göstəricilər)'!K20/3*5,1) -> 0 | L20: =ROUND('3. Cavablar (Xam Göstəricilər)'!L20/3*5,1) -> 0 | ... S20: =ROUND('3. Cavablar (Xam Göstəricilər)'!S20/3*5,1) -> 0
B21: D. MADDİ-TEXNİKİ BAZA (10 bal)
B22: D.1 | C22: Ofis və emalatxana sahəsinin mövcudluğu | D22: 3 | E22: =ROUND('3. Cavablar (Xam Göstəricilər)'!E22/3*3,1) -> 0 | F22: =ROUND('3. Cavablar (Xam Göstəricilər)'!F22/3*3,1) -> 0 | G22: =ROUND('3. Cavablar (Xam Göstəricilər)'!G22/3*3,1) -> 0 | H22: =ROUND('3. Cavablar (Xam Göstəricilər)'!H22/3*3,1) -> 0 | I22: =ROUND('3. Cavablar (Xam Göstəricilər)'!I22/3*3,1) -> 0 | J22: =ROUND('3. Cavablar (Xam Göstəricilər)'!J22/3*3,1) -> 0 | K22: =ROUND('3. Cavablar (Xam Göstəricilər)'!K22/3*3,1) -> 0 | L22: =ROUND('3. Cavablar (Xam Göstəricilər)'!L22/3*3,1) -> 0 | ... S22: =ROUND('3. Cavablar (Xam Göstəricilər)'!S22/3*3,1) -> 0
B23: D.2 | C23: İş avadanlığı və alətlərin yetərliliyi | D23: 4 | E23: =ROUND('3. Cavablar (Xam Göstəricilər)'!E23/3*4,1) -> 0 | F23: =ROUND('3. Cavablar (Xam Göstəricilər)'!F23/3*4,1) -> 0 | G23: =ROUND('3. Cavablar (Xam Göstəricilər)'!G23/3*4,1) -> 0 | H23: =ROUND('3. Cavablar (Xam Göstəricilər)'!H23/3*4,1) -> 0 | I23: =ROUND('3. Cavablar (Xam Göstəricilər)'!I23/3*4,1) -> 0 | J23: =ROUND('3. Cavablar (Xam Göstəricilər)'!J23/3*4,1) -> 0 | K23: =ROUND('3. Cavablar (Xam Göstəricilər)'!K23/3*4,1) -> 0 | L23: =ROUND('3. Cavablar (Xam Göstəricilər)'!L23/3*4,1) -> 0 | ... S23: =ROUND('3. Cavablar (Xam Göstəricilər)'!S23/3*4,1) -> 0
B24: D.3 | C24: Nəqliyyat və yük maşın parkı | D24: 3 | E24: =ROUND('3. Cavablar (Xam Göstəricilər)'!E24/3*3,1) -> 0 | F24: =ROUND('3. Cavablar (Xam Göstəricilər)'!F24/3*3,1) -> 0 | G24: =ROUND('3. Cavablar (Xam Göstəricilər)'!G24/3*3,1) -> 0 | H24: =ROUND('3. Cavablar (Xam Göstəricilər)'!H24/3*3,1) -> 0 | I24: =ROUND('3. Cavablar (Xam Göstəricilər)'!I24/3*3,1) -> 0 | J24: =ROUND('3. Cavablar (Xam Göstəricilər)'!J24/3*3,1) -> 0 | K24: =ROUND('3. Cavablar (Xam Göstəricilər)'!K24/3*3,1) -> 0 | L24: =ROUND('3. Cavablar (Xam Göstəricilər)'!L24/3*3,1) -> 0 | ... S24: =ROUND('3. Cavablar (Xam Göstəricilər)'!S24/3*3,1) -> 0
B25: E. KADR RESURSLARI (15 bal)
B26: E.1 | C26: Ümumi daimi heyət sayı | D26: 4 | E26: =IF('3. Cavablar (Xam Göstəricilər)'!E26<20,0,IF('3. Cavablar (Xam Göstəricilər)'!E26<50,ROUND(4*0.4,1),IF('3. Cavablar (Xam Göstəricilər)'!E26<100,ROUND(4*0.75,1),4))) -> 0 | F26: =IF('3. Cavablar (Xam Göstəricilər)'!F26<20,0,IF('3. Cavablar (Xam Göstəricilər)'!F26<50,ROUND(4*0.4,1),IF('3. Cavablar (Xam Göstəricilər)'!F26<100,ROUND(4*0.75,1),4))) -> 0 | G26: =IF('3. Cavablar (Xam Göstəricilər)'!G26<20,0,IF('3. Cavablar (Xam Göstəricilər)'!G26<50,ROUND(4*0.4,1),IF('3. Cavablar (Xam Göstəricilər)'!G26<100,ROUND(4*0.75,1),4))) -> 0 | H26: =IF('3. Cavablar (Xam Göstəricilər)'!H26<20,0,IF('3. Cavablar (Xam Göstəricilər)'!H26<50,ROUND(4*0.4,1),IF('3. Cavablar (Xam Göstəricilər)'!H26<100,ROUND(4*0.75,1),4))) -> 0 | I26: =IF('3. Cavablar (Xam Göstəricilər)'!I26<20,0,IF('3. Cavablar (Xam Göstəricilər)'!I26<50,ROUND(4*0.4,1),IF('3. Cavablar (Xam Göstəricilər)'!I26<100,ROUND(4*0.75,1),4))) -> 0 | J26: =IF('3. Cavablar (Xam Göstəricilər)'!J26<20,0,IF('3. Cavablar (Xam Göstəricilər)'!J26<50,ROUND(4*0.4,1),IF('3. Cavablar (Xam Göstəricilər)'!J26<100,ROUND(4*0.75,1),4))) -> 0 | K26: =IF('3. Cavablar (Xam Göstəricilər)'!K26<20,0,IF('3. Cavablar (Xam Göstəricilər)'!K26<50,ROUND(4*0.4,1),IF('3. Cavablar (Xam Göstəricilər)'!K26<100,ROUND(4*0.75,1),4))) -> 0 | L26: =IF('3. Cavablar (Xam Göstəricilər)'!L26<20,0,IF('3. Cavablar (Xam Göstəricilər)'!L26<50,ROUND(4*0.4,1),IF('3. Cavablar (Xam Göstəricilər)'!L26<100,ROUND(4*0.75,1),4))) -> 0 | ... S26: =IF('3. Cavablar (Xam Göstəricilər)'!S26<20,0,IF('3. Cavablar (Xam Göstəricilər)'!S26<50,ROUND(4*0.4,1),IF('3. Cavablar (Xam Göstəricilər)'!S26<100,ROUND(4*0.75,1),4))) -> 0
B27: E.2 | C27: Mühəndis / texniki heyət sayı | D27: 4 | E27: =IF('3. Cavablar (Xam Göstəricilər)'!E27<3,0,IF('3. Cavablar (Xam Göstəricilər)'!E27<=7,ROUND(4*0.4,1),IF('3. Cavablar (Xam Göstəricilər)'!E27<=15,ROUND(4*0.75,1),4))) -> 0 | F27: =IF('3. Cavablar (Xam Göstəricilər)'!F27<3,0,IF('3. Cavablar (Xam Göstəricilər)'!F27<=7,ROUND(4*0.4,1),IF('3. Cavablar (Xam Göstəricilər)'!F27<=15,ROUND(4*0.75,1),4))) -> 0 | G27: =IF('3. Cavablar (Xam Göstəricilər)'!G27<3,0,IF('3. Cavablar (Xam Göstəricilər)'!G27<=7,ROUND(4*0.4,1),IF('3. Cavablar (Xam Göstəricilər)'!G27<=15,ROUND(4*0.75,1),4))) -> 0 | H27: =IF('3. Cavablar (Xam Göstəricilər)'!H27<3,0,IF('3. Cavablar (Xam Göstəricilər)'!H27<=7,ROUND(4*0.4,1),IF('3. Cavablar (Xam Göstəricilər)'!H27<=15,ROUND(4*0.75,1),4))) -> 0 | I27: =IF('3. Cavablar (Xam Göstəricilər)'!I27<3,0,IF('3. Cavablar (Xam Göstəricilər)'!I27<=7,ROUND(4*0.4,1),IF('3. Cavablar (Xam Göstəricilər)'!I27<=15,ROUND(4*0.75,1),4))) -> 0 | J27: =IF('3. Cavablar (Xam Göstəricilər)'!J27<3,0,IF('3. Cavablar (Xam Göstəricilər)'!J27<=7,ROUND(4*0.4,1),IF('3. Cavablar (Xam Göstəricilər)'!J27<=15,ROUND(4*0.75,1),4))) -> 0 | K27: =IF('3. Cavablar (Xam Göstəricilər)'!K27<3,0,IF('3. Cavablar (Xam Göstəricilər)'!K27<=7,ROUND(4*0.4,1),IF('3. Cavablar (Xam Göstəricilər)'!K27<=15,ROUND(4*0.75,1),4))) -> 0 | L27: =IF('3. Cavablar (Xam Göstəricilər)'!L27<3,0,IF('3. Cavablar (Xam Göstəricilər)'!L27<=7,ROUND(4*0.4,1),IF('3. Cavablar (Xam Göstəricilər)'!L27<=15,ROUND(4*0.75,1),4))) -> 0 | ... S27: =IF('3. Cavablar (Xam Göstəricilər)'!S27<3,0,IF('3. Cavablar (Xam Göstəricilər)'!S27<=7,ROUND(4*0.4,1),IF('3. Cavablar (Xam Göstəricilər)'!S27<=15,ROUND(4*0.75,1),4))) -> 0
B28: E.3 | C28: Tam ştatlı İSG (HSE) mütəxəssisi | D28: 3 | E28: =ROUND('3. Cavablar (Xam Göstəricilər)'!E28/3*3,1) -> 0 | F28: =ROUND('3. Cavablar (Xam Göstəricilər)'!F28/3*3,1) -> 0 | G28: =ROUND('3. Cavablar (Xam Göstəricilər)'!G28/3*3,1) -> 0 | H28: =ROUND('3. Cavablar (Xam Göstəricilər)'!H28/3*3,1) -> 0 | I28: =ROUND('3. Cavablar (Xam Göstəricilər)'!I28/3*3,1) -> 0 | J28: =ROUND('3. Cavablar (Xam Göstəricilər)'!J28/3*3,1) -> 0 | K28: =ROUND('3. Cavablar (Xam Göstəricilər)'!K28/3*3,1) -> 0 | L28: =ROUND('3. Cavablar (Xam Göstəricilər)'!L28/3*3,1) -> 0 | ... S28: =ROUND('3. Cavablar (Xam Göstəricilər)'!S28/3*3,1) -> 0
B29: E.4 | C29: Daimi subpodratçı bazası | D29: 4 | E29: =ROUND('3. Cavablar (Xam Göstəricilər)'!E29/3*4,1) -> 0 | F29: =ROUND('3. Cavablar (Xam Göstəricilər)'!F29/3*4,1) -> 0 | G29: =ROUND('3. Cavablar (Xam Göstəricilər)'!G29/3*4,1) -> 0 | H29: =ROUND('3. Cavablar (Xam Göstəricilər)'!H29/3*4,1) -> 0 | I29: =ROUND('3. Cavablar (Xam Göstəricilər)'!I29/3*4,1) -> 0 | J29: =ROUND('3. Cavablar (Xam Göstəricilər)'!J29/3*4,1) -> 0 | K29: =ROUND('3. Cavablar (Xam Göstəricilər)'!K29/3*4,1) -> 0 | L29: =ROUND('3. Cavablar (Xam Göstəricilər)'!L29/3*4,1) -> 0 | ... S29: =ROUND('3. Cavablar (Xam Göstəricilər)'!S29/3*4,1) -> 0
B30: F. İSG VƏ KEYFİYYƏT (10 bal)
B31: F.1 | C31: İSG sertifikatı və planı (MƏCBURİ) | D31: 4 | E31: =ROUND('3. Cavablar (Xam Göstəricilər)'!E31/3*4,1) -> 0 | F31: =ROUND('3. Cavablar (Xam Göstəricilər)'!F31/3*4,1) -> 0 | G31: =ROUND('3. Cavablar (Xam Göstəricilər)'!G31/3*4,1) -> 0 | H31: =ROUND('3. Cavablar (Xam Göstəricilər)'!H31/3*4,1) -> 0 | I31: =ROUND('3. Cavablar (Xam Göstəricilər)'!I31/3*4,1) -> 0 | J31: =ROUND('3. Cavablar (Xam Göstəricilər)'!J31/3*4,1) -> 0 | K31: =ROUND('3. Cavablar (Xam Göstəricilər)'!K31/3*4,1) -> 0 | L31: =ROUND('3. Cavablar (Xam Göstəricilər)'!L31/3*4,1) -> 0 | ... S31: =ROUND('3. Cavablar (Xam Göstəricilər)'!S31/3*4,1) -> 0
B32: F.2 | C32: ISO 14001 / 45001 sertifikatları | D32: 3 | E32: =ROUND('3. Cavablar (Xam Göstəricilər)'!E32/3*3,1) -> 0 | F32: =ROUND('3. Cavablar (Xam Göstəricilər)'!F32/3*3,1) -> 0 | G32: =ROUND('3. Cavablar (Xam Göstəricilər)'!G32/3*3,1) -> 0 | H32: =ROUND('3. Cavablar (Xam Göstəricilər)'!H32/3*3,1) -> 0 | I32: =ROUND('3. Cavablar (Xam Göstəricilər)'!I32/3*3,1) -> 0 | J32: =ROUND('3. Cavablar (Xam Göstəricilər)'!J32/3*3,1) -> 0 | K32: =ROUND('3. Cavablar (Xam Göstəricilər)'!K32/3*3,1) -> 0 | L32: =ROUND('3. Cavablar (Xam Göstəricilər)'!L32/3*3,1) -> 0 | ... S32: =ROUND('3. Cavablar (Xam Göstəricilər)'!S32/3*3,1) -> 0
B33: F.3 | C33: Son 3 ildə bədbəxt hadisə göstəricisi | D33: 3 | E33: =ROUND('3. Cavablar (Xam Göstəricilər)'!E33/3*3,1) -> 0 | F33: =ROUND('3. Cavablar (Xam Göstəricilər)'!F33/3*3,1) -> 0 | G33: =ROUND('3. Cavablar (Xam Göstəricilər)'!G33/3*3,1) -> 0 | H33: =ROUND('3. Cavablar (Xam Göstəricilər)'!H33/3*3,1) -> 0 | I33: =ROUND('3. Cavablar (Xam Göstəricilər)'!I33/3*3,1) -> 0 | J33: =ROUND('3. Cavablar (Xam Göstəricilər)'!J33/3*3,1) -> 0 | K33: =ROUND('3. Cavablar (Xam Göstəricilər)'!K33/3*3,1) -> 0 | L33: =ROUND('3. Cavablar (Xam Göstəricilər)'!L33/3*3,1) -> 0 | ... S33: =ROUND('3. Cavablar (Xam Göstəricilər)'!S33/3*3,1) -> 0
B34: G. SIĞORTA VƏ REFERANSLAR (5 bal)
B35: G.1 | C35: Peşəkar və ümumi məsuliyyət sığortası | D35: 3 | E35: =ROUND('3. Cavablar (Xam Göstəricilər)'!E35/3*3,1) -> 0 | F35: =ROUND('3. Cavablar (Xam Göstəricilər)'!F35/3*3,1) -> 0 | G35: =ROUND('3. Cavablar (Xam Göstəricilər)'!G35/3*3,1) -> 0 | H35: =ROUND('3. Cavablar (Xam Göstəricilər)'!H35/3*3,1) -> 0 | I35: =ROUND('3. Cavablar (Xam Göstəricilər)'!I35/3*3,1) -> 0 | J35: =ROUND('3. Cavablar (Xam Göstəricilər)'!J35/3*3,1) -> 0 | K35: =ROUND('3. Cavablar (Xam Göstəricilər)'!K35/3*3,1) -> 0 | L35: =ROUND('3. Cavablar (Xam Göstəricilər)'!L35/3*3,1) -> 0 | ... S35: =ROUND('3. Cavablar (Xam Göstəricilər)'!S35/3*3,1) -> 0
B36: G.2 | C36: Keçmiş müştərilərdən referans sayı | D36: 2 | E36: =IF('3. Cavablar (Xam Göstəricilər)'!E36=0,0,IF('3. Cavablar (Xam Göstəricilər)'!E36<=2,ROUND(2*0.4,1),IF('3. Cavablar (Xam Göstəricilər)'!E36<=5,ROUND(2*0.7,1),2))) -> 0 | F36: =IF('3. Cavablar (Xam Göstəricilər)'!F36=0,0,IF('3. Cavablar (Xam Göstəricilər)'!F36<=2,ROUND(2*0.4,1),IF('3. Cavablar (Xam Göstəricilər)'!F36<=5,ROUND(2*0.7,1),2))) -> 0 | G36: =IF('3. Cavablar (Xam Göstəricilər)'!G36=0,0,IF('3. Cavablar (Xam Göstəricilər)'!G36<=2,ROUND(2*0.4,1),IF('3. Cavablar (Xam Göstəricilər)'!G36<=5,ROUND(2*0.7,1),2))) -> 0 | H36: =IF('3. Cavablar (Xam Göstəricilər)'!H36=0,0,IF('3. Cavablar (Xam Göstəricilər)'!H36<=2,ROUND(2*0.4,1),IF('3. Cavablar (Xam Göstəricilər)'!H36<=5,ROUND(2*0.7,1),2))) -> 0 | I36: =IF('3. Cavablar (Xam Göstəricilər)'!I36=0,0,IF('3. Cavablar (Xam Göstəricilər)'!I36<=2,ROUND(2*0.4,1),IF('3. Cavablar (Xam Göstəricilər)'!I36<=5,ROUND(2*0.7,1),2))) -> 0 | J36: =IF('3. Cavablar (Xam Göstəricilər)'!J36=0,0,IF('3. Cavablar (Xam Göstəricilər)'!J36<=2,ROUND(2*0.4,1),IF('3. Cavablar (Xam Göstəricilər)'!J36<=5,ROUND(2*0.7,1),2))) -> 0 | K36: =IF('3. Cavablar (Xam Göstəricilər)'!K36=0,0,IF('3. Cavablar (Xam Göstəricilər)'!K36<=2,ROUND(2*0.4,1),IF('3. Cavablar (Xam Göstəricilər)'!K36<=5,ROUND(2*0.7,1),2))) -> 0 | L36: =IF('3. Cavablar (Xam Göstəricilər)'!L36=0,0,IF('3. Cavablar (Xam Göstəricilər)'!L36<=2,ROUND(2*0.4,1),IF('3. Cavablar (Xam Göstəricilər)'!L36<=5,ROUND(2*0.7,1),2))) -> 0 | ... S36: =IF('3. Cavablar (Xam Göstəricilər)'!S36=0,0,IF('3. Cavablar (Xam Göstəricilər)'!S36<=2,ROUND(2*0.4,1),IF('3. Cavablar (Xam Göstəricilər)'!S36<=5,ROUND(2*0.7,1),2))) -> 0
B38: QRUP CƏMLƏRİ VƏ ÜMUMİ BAL
B39: A | C39: Şirkət Profili — qrup cəmi | D39: 15 | E39: =E7+E8+E9+E10 -> 0 | F39: =F7+F8+F9+F10 -> 0 | G39: =G7+G8+G9+G10 -> 0 | H39: =H7+H8+H9+H10 -> 0 | I39: =I7+I8+I9+I10 -> 0 | J39: =J7+J8+J9+J10 -> 0 | K39: =K7+K8+K9+K10 -> 0 | L39: =L7+L8+L9+L10 -> 0 | ... S39: =S7+S8+S9+S10 -> 0
B40: B | C40: Maliyyə — qrup cəmi | D40: 20 | E40: =E12+E13+E14+E15 -> 0 | F40: =F12+F13+F14+F15 -> 0 | G40: =G12+G13+G14+G15 -> 0 | H40: =H12+H13+H14+H15 -> 0 | I40: =I12+I13+I14+I15 -> 0 | J40: =J12+J13+J14+J15 -> 0 | K40: =K12+K13+K14+K15 -> 0 | L40: =L12+L13+L14+L15 -> 0 | ... S40: =S12+S13+S14+S15 -> 0
B41: C | C41: Texniki Təcrübə — qrup cəmi | D41: 25 | E41: =E17+E18+E19+E20 -> 1 | F41: =F17+F18+F19+F20 -> 1 | G41: =G17+G18+G19+G20 -> 1 | H41: =H17+H18+H19+H20 -> 1 | I41: =I17+I18+I19+I20 -> 1 | J41: =J17+J18+J19+J20 -> 1 | K41: =K17+K18+K19+K20 -> 1 | L41: =L17+L18+L19+L20 -> 1 | ... S41: =S17+S18+S19+S20 -> 1
B42: D | C42: Maddi-Texniki Baza — qrup cəmi | D42: 10 | E42: =E22+E23+E24 -> 0 | F42: =F22+F23+F24 -> 0 | G42: =G22+G23+G24 -> 0 | H42: =H22+H23+H24 -> 0 | I42: =I22+I23+I24 -> 0 | J42: =J22+J23+J24 -> 0 | K42: =K22+K23+K24 -> 0 | L42: =L22+L23+L24 -> 0 | ... S42: =S22+S23+S24 -> 0
B43: E | C43: Kadr Resursları — qrup cəmi | D43: 15 | E43: =E26+E27+E28+E29 -> 0 | F43: =F26+F27+F28+F29 -> 0 | G43: =G26+G27+G28+G29 -> 0 | H43: =H26+H27+H28+H29 -> 0 | I43: =I26+I27+I28+I29 -> 0 | J43: =J26+J27+J28+J29 -> 0 | K43: =K26+K27+K28+K29 -> 0 | L43: =L26+L27+L28+L29 -> 0 | ... S43: =S26+S27+S28+S29 -> 0
...

Sheet 5. Nəticə Xülasəsi
B2: PREKVALİFİKASİYA NƏTİCƏLƏRİ — İCRAİ XÜLASƏ
B3: Rəhbərliyin Təsdiqi üçün | Tenderə Dəvət Edilməli İştirakçıların Müəyyən edilməsi
B5: Göstərici | C5: İştirakçı №1 | D5: İştirakçı №2 | E5: İştirakçı №3 | F5: İştirakçı №4 | G5: İştirakçı №5 | H5: İştirakçı №6 | I5: İştirakçı №7 | J5: İştirakçı №8 | K5: İştirakçı №9 | L5: İştirakçı №10 | M5: İştirakçı №11 | N5: İştirakçı №12 | O5: İştirakçı №13 | P5: İştirakçı №14 | Q5: İştirakçı №15
B6: Şirkətin Adı | C6: ='2. İştirakçı Məlumatları'!C6 -> 0 | D6: ='2. İştirakçı Məlumatları'!D6 -> 0 | E6: ='2. İştirakçı Məlumatları'!E6 -> 0 | F6: ='2. İştirakçı Məlumatları'!F6 -> 0 | G6: ='2. İştirakçı Məlumatları'!G6 -> 0 | H6: ='2. İştirakçı Məlumatları'!H6 -> 0 | I6: ='2. İştirakçı Məlumatları'!I6 -> 0 | J6: ='2. İştirakçı Məlumatları'!J6 -> 0 | ... Q6: ='2. İştirakçı Məlumatları'!Q6 -> 0
B7: Qeydiyyat ili | C7: ='2. İştirakçı Məlumatları'!C8 -> 0 | D7: ='2. İştirakçı Məlumatları'!D8 -> 0 | E7: ='2. İştirakçı Məlumatları'!E8 -> 0 | F7: ='2. İştirakçı Məlumatları'!F8 -> 0 | G7: ='2. İştirakçı Məlumatları'!G8 -> 0 | H7: ='2. İştirakçı Məlumatları'!H8 -> 0 | I7: ='2. İştirakçı Məlumatları'!I8 -> 0 | J7: ='2. İştirakçı Məlumatları'!J8 -> 0 | ... Q7: ='2. İştirakçı Məlumatları'!Q8 -> 0
B8: Ümumi heyət sayı | C8: ='2. İştirakçı Məlumatları'!C15 -> 0 | D8: ='2. İştirakçı Məlumatları'!D15 -> 0 | E8: ='2. İştirakçı Məlumatları'!E15 -> 0 | F8: ='2. İştirakçı Məlumatları'!F15 -> 0 | G8: ='2. İştirakçı Məlumatları'!G15 -> 0 | H8: ='2. İştirakçı Məlumatları'!H15 -> 0 | I8: ='2. İştirakçı Məlumatları'!I15 -> 0 | J8: ='2. İştirakçı Məlumatları'!J15 -> 0 | ... Q8: ='2. İştirakçı Məlumatları'!Q15 -> 0
B9: Əlaqə şəxsi | C9: ='2. İştirakçı Məlumatları'!C10 -> 0 | D9: ='2. İştirakçı Məlumatları'!D10 -> 0 | E9: ='2. İştirakçı Məlumatları'!E10 -> 0 | F9: ='2. İştirakçı Məlumatları'!F10 -> 0 | G9: ='2. İştirakçı Məlumatları'!G10 -> 0 | H9: ='2. İştirakçı Məlumatları'!H10 -> 0 | I9: ='2. İştirakçı Məlumatları'!I10 -> 0 | J9: ='2. İştirakçı Məlumatları'!J10 -> 0 | ... Q9: ='2. İştirakçı Məlumatları'!Q10 -> 0
B10: Telefon | C10: ='2. İştirakçı Məlumatları'!C12 -> 0 | D10: ='2. İştirakçı Məlumatları'!D12 -> 0 | E10: ='2. İştirakçı Məlumatları'!E12 -> 0 | F10: ='2. İştirakçı Məlumatları'!F12 -> 0 | G10: ='2. İştirakçı Məlumatları'!G12 -> 0 | H10: ='2. İştirakçı Məlumatları'!H12 -> 0 | I10: ='2. İştirakçı Məlumatları'!I12 -> 0 | J10: ='2. İştirakçı Məlumatları'!J12 -> 0 | ... Q10: ='2. İştirakçı Məlumatları'!Q12 -> 0
B12: BAL DETALI (Qrup üzrə)
B13: A. Şirkət Profili (/15) | C13: ='4. Bal Hesablaması'!E39 -> 0 | D13: ='4. Bal Hesablaması'!F39 -> 0 | E13: ='4. Bal Hesablaması'!G39 -> 0 | F13: ='4. Bal Hesablaması'!H39 -> 0 | G13: ='4. Bal Hesablaması'!I39 -> 0 | H13: ='4. Bal Hesablaması'!J39 -> 0 | I13: ='4. Bal Hesablaması'!K39 -> 0 | J13: ='4. Bal Hesablaması'!L39 -> 0 | ... Q13: ='4. Bal Hesablaması'!S39 -> 0
B14: B. Maliyyə (/20) | C14: ='4. Bal Hesablaması'!E40 -> 0 | D14: ='4. Bal Hesablaması'!F40 -> 0 | E14: ='4. Bal Hesablaması'!G40 -> 0 | F14: ='4. Bal Hesablaması'!H40 -> 0 | G14: ='4. Bal Hesablaması'!I40 -> 0 | H14: ='4. Bal Hesablaması'!J40 -> 0 | I14: ='4. Bal Hesablaması'!K40 -> 0 | J14: ='4. Bal Hesablaması'!L40 -> 0 | ... Q14: ='4. Bal Hesablaması'!S40 -> 0
B15: C. Texniki Təcrübə (/25) | C15: ='4. Bal Hesablaması'!E41 -> 1 | D15: ='4. Bal Hesablaması'!F41 -> 1 | E15: ='4. Bal Hesablaması'!G41 -> 1 | F15: ='4. Bal Hesablaması'!H41 -> 1 | G15: ='4. Bal Hesablaması'!I41 -> 1 | H15: ='4. Bal Hesablaması'!J41 -> 1 | I15: ='4. Bal Hesablaması'!K41 -> 1 | J15: ='4. Bal Hesablaması'!L41 -> 1 | ... Q15: ='4. Bal Hesablaması'!S41 -> 1
B16: D. Maddi-Texniki (/10) | C16: ='4. Bal Hesablaması'!E42 -> 0 | D16: ='4. Bal Hesablaması'!F42 -> 0 | E16: ='4. Bal Hesablaması'!G42 -> 0 | F16: ='4. Bal Hesablaması'!H42 -> 0 | G16: ='4. Bal Hesablaması'!I42 -> 0 | H16: ='4. Bal Hesablaması'!J42 -> 0 | I16: ='4. Bal Hesablaması'!K42 -> 0 | J16: ='4. Bal Hesablaması'!L42 -> 0 | ... Q16: ='4. Bal Hesablaması'!S42 -> 0
B17: E. Kadr (/15) | C17: ='4. Bal Hesablaması'!E43 -> 0 | D17: ='4. Bal Hesablaması'!F43 -> 0 | E17: ='4. Bal Hesablaması'!G43 -> 0 | F17: ='4. Bal Hesablaması'!H43 -> 0 | G17: ='4. Bal Hesablaması'!I43 -> 0 | H17: ='4. Bal Hesablaması'!J43 -> 0 | I17: ='4. Bal Hesablaması'!K43 -> 0 | J17: ='4. Bal Hesablaması'!L43 -> 0 | ... Q17: ='4. Bal Hesablaması'!S43 -> 0
B18: F. İSG (/10) | C18: ='4. Bal Hesablaması'!E44 -> 0 | D18: ='4. Bal Hesablaması'!F44 -> 0 | E18: ='4. Bal Hesablaması'!G44 -> 0 | F18: ='4. Bal Hesablaması'!H44 -> 0 | G18: ='4. Bal Hesablaması'!I44 -> 0 | H18: ='4. Bal Hesablaması'!J44 -> 0 | I18: ='4. Bal Hesablaması'!K44 -> 0 | J18: ='4. Bal Hesablaması'!L44 -> 0 | ... Q18: ='4. Bal Hesablaması'!S44 -> 0
B19: G. Sığorta & Ref. (/5) | C19: ='4. Bal Hesablaması'!E45 -> 0 | D19: ='4. Bal Hesablaması'!F45 -> 0 | E19: ='4. Bal Hesablaması'!G45 -> 0 | F19: ='4. Bal Hesablaması'!H45 -> 0 | G19: ='4. Bal Hesablaması'!I45 -> 0 | H19: ='4. Bal Hesablaması'!J45 -> 0 | I19: ='4. Bal Hesablaması'!K45 -> 0 | J19: ='4. Bal Hesablaması'!L45 -> 0 | ... Q19: ='4. Bal Hesablaması'!S45 -> 0
B21: ÜMUMİ BAL (100) | C21: ='4. Bal Hesablaması'!E46 -> 1 | D21: ='4. Bal Hesablaması'!F46 -> 1 | E21: ='4. Bal Hesablaması'!G46 -> 1 | F21: ='4. Bal Hesablaması'!H46 -> 1 | G21: ='4. Bal Hesablaması'!I46 -> 1 | H21: ='4. Bal Hesablaması'!J46 -> 1 | I21: ='4. Bal Hesablaması'!K46 -> 1 | J21: ='4. Bal Hesablaması'!L46 -> 1 | ... Q21: ='4. Bal Hesablaması'!S46 -> 1
B22: Məcburi Meyar (KO) | C22: ='4. Bal Hesablaması'!E48 -> RƏDD ✗ | D22: ='4. Bal Hesablaması'!F48 -> RƏDD ✗ | E22: ='4. Bal Hesablaması'!G48 -> RƏDD ✗ | F22: ='4. Bal Hesablaması'!H48 -> RƏDD ✗ | G22: ='4. Bal Hesablaması'!I48 -> RƏDD ✗ | H22: ='4. Bal Hesablaması'!J48 -> RƏDD ✗ | I22: ='4. Bal Hesablaması'!K48 -> RƏDD ✗ | J22: ='4. Bal Hesablaması'!L48 -> RƏDD ✗ | ... Q22: ='4. Bal Hesablaması'!S48 -> RƏDD ✗
B23: NƏTİCƏ / TÖVSİYƏ | C23: ='4. Bal Hesablaması'!E49 -> KO — RƏDD | D23: ='4. Bal Hesablaması'!F49 -> KO — RƏDD | E23: ='4. Bal Hesablaması'!G49 -> KO — RƏDD | F23: ='4. Bal Hesablaması'!H49 -> KO — RƏDD | G23: ='4. Bal Hesablaması'!I49 -> KO — RƏDD | H23: ='4. Bal Hesablaması'!J49 -> KO — RƏDD | I23: ='4. Bal Hesablaması'!K49 -> KO — RƏDD | J23: ='4. Bal Hesablaması'!L49 -> KO — RƏDD | ... Q23: ='4. Bal Hesablaması'!S49 -> KO — RƏDD
B26: KOMİSSİYANIN QEYDLƏRİ VƏ ƏSASLANDIRMA
B27: 90+ bal toplamış iştirakçılar A sinifi — birinci prioritetlə tenderə dəvət edilir. 80–89 bal (B sinfi) da dəvət edilir. 70–79 bal (C) şərti dəvət. 60–69 bal (D) və aşağı (F) — tenderə dəvət edilmir. Məcburi meyarlardan birini təmin etməyən — avtomatik RƏDD.
B32: Komissiya Sədri / Tarix: | J32: Rəhbərin Təsdiqi / Tarix:
